# Throw signals an error

`throw()` throws an exception at the location of the `yield` that led to the last suspension of the generator. Letâ€™s examine how that works via the following generator function.

```javascript
function* genFunc1() {
  try {
    console.log('Started');
    yield; // (A)
  } catch (error) {
    console.log('Caught: ' + error);
  }
}
```

In the following interaction, we first use `next()` to start the generator and proceed until the `yield` in line A. Then we throw an exception from that location.

```javascript
> const genObj1 = genFunc1();

> genObj1.next()
Started
{ value: undefined, done: false }

> genObj1.throw(new Error('Problem!'))
Caught: Error: Problem!
{ value: undefined, done: true }
```

The result of `throw()` \(shown in the last line\) stems from us leaving the function with an implicit `return`.

{% tabs %}
{% tab title="Exercise" %}
When executing promises, while running a generator errors can be thrown. We can propagate those errors now back to the generator. 

```javascript
function runGenerator(genFunc) {
  const genObj = genFunc();
  step(genObj.next());

  function step({ value, done }) {
    if (!done) {
      value
        .then(() => {
          step(genObj.next());
        })
        // implement propogating errors
    }
  }
}

```
{% endtab %}

{% tab title="Solution" %}
```javascript
function runGenerator(genFunc) {
  const genObj = genFunc();
  step(genObj.next());

  function step({ value, done }) {
    if (!done) {
      value
        .then(() => {
          step(genObj.next());
        })
        .catch((error) => {
          step(genObj.throw(error));
        });
    }
  }
}

```
{% endtab %}
{% endtabs %}



